2018-04-24 19:39:30,751 INFO: Microblog startup [in /Users/ninatunas/PycharmProjects/flask_login/app/__init__.py:49]
2018-04-24 19:39:32,232 INFO: Microblog startup [in /Users/ninatunas/PycharmProjects/flask_login/app/__init__.py:49]
2018-04-26 09:13:35,074 INFO: Microblog startup [in /Users/ninatunas/PycharmProjects/flask_login/app/__init__.py:49]
2018-04-26 09:14:20,846 INFO: Microblog startup [in /Users/ninatunas/PycharmProjects/flask_login/app/__init__.py:49]
2018-04-28 17:49:04,303 INFO: Microblog startup [in /Users/ninatunas/PycharmProjects/flask_login/app/__init__.py:49]
2018-04-28 17:58:20,207 INFO: Microblog startup [in /Users/ninatunas/PycharmProjects/flask_login/app/__init__.py:49]
2018-04-28 18:05:55,809 INFO: Microblog startup [in /Users/ninatunas/PycharmProjects/flask_login/app/__init__.py:49]
2018-04-28 18:06:03,723 ERROR: Exception on /index [GET] [in /Users/ninatunas/anaconda/lib/python3.5/site-packages/flask/app.py:1587]
Traceback (most recent call last):
  File "/Users/ninatunas/anaconda/lib/python3.5/site-packages/flask/app.py", line 1988, in wsgi_app
    response = self.full_dispatch_request()
  File "/Users/ninatunas/anaconda/lib/python3.5/site-packages/flask/app.py", line 1641, in full_dispatch_request
    rv = self.handle_user_exception(e)
  File "/Users/ninatunas/anaconda/lib/python3.5/site-packages/flask/app.py", line 1544, in handle_user_exception
    reraise(exc_type, exc_value, tb)
  File "/Users/ninatunas/anaconda/lib/python3.5/site-packages/flask/_compat.py", line 33, in reraise
    raise value
  File "/Users/ninatunas/anaconda/lib/python3.5/site-packages/flask/app.py", line 1639, in full_dispatch_request
    rv = self.dispatch_request()
  File "/Users/ninatunas/anaconda/lib/python3.5/site-packages/flask/app.py", line 1625, in dispatch_request
    return self.view_functions[rule.endpoint](**req.view_args)
  File "/Users/ninatunas/anaconda/lib/python3.5/site-packages/flask_login/utils.py", line 261, in decorated_view
    return func(*args, **kwargs)
  File "/Users/ninatunas/PycharmProjects/flask_login/app/routes.py", line 26, in index
    return render_template('index.html',title='Home', posts=current_user.followed_post())
  File "/Users/ninatunas/anaconda/lib/python3.5/site-packages/werkzeug/local.py", line 343, in __getattr__
    return getattr(self._get_current_object(), name)
AttributeError: 'User' object has no attribute 'followed_post'
2018-04-28 18:06:07,952 ERROR: Exception on /index [GET] [in /Users/ninatunas/anaconda/lib/python3.5/site-packages/flask/app.py:1587]
Traceback (most recent call last):
  File "/Users/ninatunas/anaconda/lib/python3.5/site-packages/flask/app.py", line 1988, in wsgi_app
    response = self.full_dispatch_request()
  File "/Users/ninatunas/anaconda/lib/python3.5/site-packages/flask/app.py", line 1641, in full_dispatch_request
    rv = self.handle_user_exception(e)
  File "/Users/ninatunas/anaconda/lib/python3.5/site-packages/flask/app.py", line 1544, in handle_user_exception
    reraise(exc_type, exc_value, tb)
  File "/Users/ninatunas/anaconda/lib/python3.5/site-packages/flask/_compat.py", line 33, in reraise
    raise value
  File "/Users/ninatunas/anaconda/lib/python3.5/site-packages/flask/app.py", line 1639, in full_dispatch_request
    rv = self.dispatch_request()
  File "/Users/ninatunas/anaconda/lib/python3.5/site-packages/flask/app.py", line 1625, in dispatch_request
    return self.view_functions[rule.endpoint](**req.view_args)
  File "/Users/ninatunas/anaconda/lib/python3.5/site-packages/flask_login/utils.py", line 261, in decorated_view
    return func(*args, **kwargs)
  File "/Users/ninatunas/PycharmProjects/flask_login/app/routes.py", line 26, in index
    return render_template('index.html',title='Home', posts=current_user.followed_post())
  File "/Users/ninatunas/anaconda/lib/python3.5/site-packages/werkzeug/local.py", line 343, in __getattr__
    return getattr(self._get_current_object(), name)
AttributeError: 'User' object has no attribute 'followed_post'
2018-04-28 18:06:10,966 ERROR: Exception on /index [GET] [in /Users/ninatunas/anaconda/lib/python3.5/site-packages/flask/app.py:1587]
Traceback (most recent call last):
  File "/Users/ninatunas/anaconda/lib/python3.5/site-packages/flask/app.py", line 1988, in wsgi_app
    response = self.full_dispatch_request()
  File "/Users/ninatunas/anaconda/lib/python3.5/site-packages/flask/app.py", line 1641, in full_dispatch_request
    rv = self.handle_user_exception(e)
  File "/Users/ninatunas/anaconda/lib/python3.5/site-packages/flask/app.py", line 1544, in handle_user_exception
    reraise(exc_type, exc_value, tb)
  File "/Users/ninatunas/anaconda/lib/python3.5/site-packages/flask/_compat.py", line 33, in reraise
    raise value
  File "/Users/ninatunas/anaconda/lib/python3.5/site-packages/flask/app.py", line 1639, in full_dispatch_request
    rv = self.dispatch_request()
  File "/Users/ninatunas/anaconda/lib/python3.5/site-packages/flask/app.py", line 1625, in dispatch_request
    return self.view_functions[rule.endpoint](**req.view_args)
  File "/Users/ninatunas/anaconda/lib/python3.5/site-packages/flask_login/utils.py", line 261, in decorated_view
    return func(*args, **kwargs)
  File "/Users/ninatunas/PycharmProjects/flask_login/app/routes.py", line 26, in index
    return render_template('index.html',title='Home', posts=current_user.followed_post())
  File "/Users/ninatunas/anaconda/lib/python3.5/site-packages/werkzeug/local.py", line 343, in __getattr__
    return getattr(self._get_current_object(), name)
AttributeError: 'User' object has no attribute 'followed_post'
2018-04-28 18:06:12,822 ERROR: Exception on /index [GET] [in /Users/ninatunas/anaconda/lib/python3.5/site-packages/flask/app.py:1587]
Traceback (most recent call last):
  File "/Users/ninatunas/anaconda/lib/python3.5/site-packages/flask/app.py", line 1988, in wsgi_app
    response = self.full_dispatch_request()
  File "/Users/ninatunas/anaconda/lib/python3.5/site-packages/flask/app.py", line 1641, in full_dispatch_request
    rv = self.handle_user_exception(e)
  File "/Users/ninatunas/anaconda/lib/python3.5/site-packages/flask/app.py", line 1544, in handle_user_exception
    reraise(exc_type, exc_value, tb)
  File "/Users/ninatunas/anaconda/lib/python3.5/site-packages/flask/_compat.py", line 33, in reraise
    raise value
  File "/Users/ninatunas/anaconda/lib/python3.5/site-packages/flask/app.py", line 1639, in full_dispatch_request
    rv = self.dispatch_request()
  File "/Users/ninatunas/anaconda/lib/python3.5/site-packages/flask/app.py", line 1625, in dispatch_request
    return self.view_functions[rule.endpoint](**req.view_args)
  File "/Users/ninatunas/anaconda/lib/python3.5/site-packages/flask_login/utils.py", line 261, in decorated_view
    return func(*args, **kwargs)
  File "/Users/ninatunas/PycharmProjects/flask_login/app/routes.py", line 26, in index
    return render_template('index.html',title='Home', posts=current_user.followed_post())
  File "/Users/ninatunas/anaconda/lib/python3.5/site-packages/werkzeug/local.py", line 343, in __getattr__
    return getattr(self._get_current_object(), name)
AttributeError: 'User' object has no attribute 'followed_post'
2018-04-28 18:06:42,714 ERROR: Exception on /index [GET] [in /Users/ninatunas/anaconda/lib/python3.5/site-packages/flask/app.py:1587]
Traceback (most recent call last):
  File "/Users/ninatunas/anaconda/lib/python3.5/site-packages/flask/app.py", line 1988, in wsgi_app
    response = self.full_dispatch_request()
  File "/Users/ninatunas/anaconda/lib/python3.5/site-packages/flask/app.py", line 1641, in full_dispatch_request
    rv = self.handle_user_exception(e)
  File "/Users/ninatunas/anaconda/lib/python3.5/site-packages/flask/app.py", line 1544, in handle_user_exception
    reraise(exc_type, exc_value, tb)
  File "/Users/ninatunas/anaconda/lib/python3.5/site-packages/flask/_compat.py", line 33, in reraise
    raise value
  File "/Users/ninatunas/anaconda/lib/python3.5/site-packages/flask/app.py", line 1639, in full_dispatch_request
    rv = self.dispatch_request()
  File "/Users/ninatunas/anaconda/lib/python3.5/site-packages/flask/app.py", line 1625, in dispatch_request
    return self.view_functions[rule.endpoint](**req.view_args)
  File "/Users/ninatunas/anaconda/lib/python3.5/site-packages/flask_login/utils.py", line 261, in decorated_view
    return func(*args, **kwargs)
  File "/Users/ninatunas/PycharmProjects/flask_login/app/routes.py", line 26, in index
    return render_template('index.html',title='Home', posts=current_user.followed_post())
  File "/Users/ninatunas/anaconda/lib/python3.5/site-packages/werkzeug/local.py", line 343, in __getattr__
    return getattr(self._get_current_object(), name)
AttributeError: 'User' object has no attribute 'followed_post'
